<?xml version="1.0"?>
<robot xmlns:xacro="http://www.ros.org/wiki/xacro" name="laika">
  <!-- MATERIALS -->
  <material name="body">
    <color rgba="0.6 0.3 0.3 1"/>
  </material>
  <material name="hip">
    <color rgba="0.8 0.4 0.7 1"/>
  </material>
  <material name="upper">
    <color rgba="0.5 0.2 0.1 1"/>
  </material>
  <material name="lower">
    <color rgba="0.3 0.4 0.6 1"/>
  </material>
  <material name="feet">
    <color rgba="0.8 0.2 0.1 1"/>
  </material>

  <!-- CONSTANTS -->
  <xacro:property name="damping" value="0.2" />
  <xacro:property name="friction" value="0.01" />

  <!-- Make Laika fly in the air -->
  <link name="world"/>
  <joint name="world_to_base" type="fixed">
    <origin rpy="0 0 ${pi}" xyz="0 0 1"/>
    <parent link="world"/>
    <child link="base"/>
  </joint>

  <!-- SPHERES AT THE END -->
  <link name="fl_sphere">
    <visual>
      <geometry>
        <sphere radius="0.02" />
      </geometry>
      <material name="feet"/>
    </visual>
    <collision>
      <geometry>
        <sphere radius="0.02" />
      </geometry>
    </collision>
  </link>
  <link name="fr_sphere">
    <visual>
      <geometry>
        <sphere radius="0.02" />
      </geometry>
      <material name="feet"/>
    </visual>
    <collision>
      <geometry>
        <sphere radius="0.02" />
      </geometry>
    </collision>
  </link>
  <link name="bl_sphere">
    <visual>
      <geometry>
        <sphere radius="0.02" />
      </geometry>
      <material name="feet"/>
    </visual>
    <collision>
      <geometry>
        <sphere radius="0.02" />
      </geometry>
    </collision>
  </link>
  <link name="br_sphere">
    <visual>
      <geometry>
        <sphere radius="0.02" />
      </geometry>
      <material name="feet"/>
    </visual>
    <collision>
      <geometry>
        <sphere radius="0.02" />
      </geometry>
    </collision>
  </link>
  <joint name="fl_foot" type="fixed">
    <origin rpy="0 0 0" xyz="-0.4 -0.05 0.015"/>
    <parent link="fl_lower_link"/>
    <child link="fl_sphere"/>
  </joint>
  <joint name="fr_foot" type="fixed">
    <origin rpy="0 0 0" xyz="-0.4 -0.05 0.015"/>
    <parent link="fr_lower_link"/>
    <child link="fr_sphere"/>
  </joint>
  <joint name="bl_foot" type="fixed">
    <origin rpy="0 0 0" xyz="-0.4 -0.05 0.015"/>
    <parent link="bl_lower_link"/>
    <child link="bl_sphere"/>
  </joint>
  <joint name="br_foot" type="fixed">
    <origin rpy="0 0 0" xyz="-0.4 -0.05 0.015"/>
    <parent link="br_lower_link"/>
    <child link="br_sphere"/>
  </joint>

  <!-- Added to avoid warning about base link having inertia -->
  <link name="base"/>
  <joint name="base_to_body" type="fixed">
    <origin rpy="0 0 0" xyz="0 0 0"/>
    <parent link="base"/>
    <child link="body_link"/>
  </joint>

  <link name="body_link">
    <visual>
      <origin rpy="0 0 0" xyz="0 0 0"/>
      <geometry>
        <mesh filename="$(find laika_sim)/meshes/body_link.STL"/>
      </geometry>
      <material name="body"/>
    </visual>
    <collision>
      <origin rpy="0 0 0" xyz="0 0 0"/>
      <geometry>
        <mesh filename="$(find laika_sim)/meshes/body_link.STL"/>
      </geometry>
    </collision>
    <inertial>
      <origin rpy="0 0 0" xyz="1.4272E-17 6.0167E-18 0.098263"/>
      <mass value="17.196"/>
      <inertia ixx="0.40098" ixy="-4.2352E-18" ixz="-3.2762E-18" iyy="0.10245" iyz="2.0166E-17" izz="0.41797"/>
    </inertial>
  </link>

  <!-- FL LINKS -->
  <link name="fl_hip_link">
    <visual>
      <origin rpy="0 0 0" xyz="0 0 0"/>
      <geometry>
        <mesh filename="$(find laika_sim)/meshes/fl_hip_link.STL"/>
      </geometry>
      <material name="hip"/>
    </visual>
    <collision>
      <origin rpy="0 0 0" xyz="0 0 0"/>
      <geometry>
        <mesh filename="$(find laika_sim)/meshes/fl_hip_link.STL"/>
      </geometry>
    </collision>
    <inertial>
      <origin rpy="0 0 0" xyz="-1.9392E-08 -0.0031976 0.0477"/>
      <mass value="1.6958"/>
      <inertia ixx="0.0058498" ixy="2.112E-10" ixz="-4.0096E-11" iyy="0.0030459" iyz="-0.00030042" izz="0.0066374"/>
    </inertial>
  </link>
  <link name="fl_upper_link">
    <inertial>
      <origin rpy="0 0 0" xyz="0.13279 0 0.018"/>
      <mass value="0.97882"/>
      <inertia ixx="0.00063207" ixy="-1.319E-19" ixz="1.0666E-19" iyy="0.010367" iyz="2.9899E-20" izz="0.010777"/>
    </inertial>
    <visual>
      <origin rpy="0 0 0" xyz="0 0 0"/>
      <geometry>
        <mesh filename="$(find laika_sim)/meshes/fl_upper_link.STL"/>
      </geometry>
      <material name="upper"/>
    </visual>
    <collision>
      <origin rpy="0 0 0" xyz="0 0 0"/>
      <geometry>
        <mesh filename="$(find laika_sim)/meshes/fl_upper_link.STL"/>
      </geometry>
    </collision>
  </link>
  <link name="fl_lower_link">
    <inertial>
      <origin rpy="0 0 0" xyz="-0.156194569361722 -0.0439524151267173 0.0125"/>
      <mass value="0.262408631372316"/>
      <inertia ixx="7.87592224730255E-05" ixy="-0.000247209665534184" ixz="1.36427507036098E-19" iyy="0.00476565441187624" iyz="1.51028668152663E-20" izz="0.00482182622024161"/>
    </inertial>
    <visual>
      <origin rpy="0 0 0" xyz="0 0 0"/>
      <geometry>
        <mesh filename="$(find laika_sim)/meshes/fl_lower_link.STL"/>
      </geometry>
      <material name="lower"/>
    </visual>
    <collision>
      <origin rpy="0 0 0" xyz="0 0 0"/>
      <geometry>
        <mesh filename="$(find laika_sim)/meshes/fl_lower_link.STL"/>
      </geometry>
    </collision>
  </link>

  <!-- FL JOINTS -->
  <joint name="fl_lat_joint" type="revolute">
    <origin rpy="1.5708 0 1.5708" xyz="0.043 -0.3075 0.116"/>
    <parent link="body_link"/>
    <child link="fl_hip_link"/>
    <axis xyz="1 0 0"/>
    <limit effort="100" lower="-0.5" upper="0.3" velocity="100"/>
    <dynamics damping="${damping}" friction="${friction}"/>
  </joint>
  <joint name="fl_hip_joint" type="revolute">
    <origin rpy="0 0 0" xyz="0 -0.046 0.09"/>
    <parent link="fl_hip_link"/>
    <child link="fl_upper_link"/>
    <axis xyz="0 0 -1"/>
    <limit effort="100" lower="0" upper="${pi/2}" velocity="100"/>
    <dynamics damping="${damping}" friction="${friction}"/>
  </joint>
  <joint name="fl_knee_joint" type="revolute">
    <origin rpy="0 0 0.04573" xyz="0.35 0 0.0055"/>
    <parent link="fl_upper_link"/>
    <child link="fl_lower_link"/>
    <axis xyz="0 0 1"/>
    <limit effort="100" lower="0" upper="${pi}" velocity="100"/>
    <dynamics damping="${damping}" friction="${friction}"/>
  </joint>

  <!-- FR LINKS -->
  <link name="fr_hip_link">
    <inertial>
      <origin rpy="0 0 0" xyz="-1.93920088320532E-08 0.00319763205128835 -0.0477002276240959"/>
      <mass value="1.69584433341635"/>
      <inertia ixx="0.00584981474763869" ixy="-2.11198615336347E-10" ixz="4.00957613383728E-11" iyy="0.00304591016123344" iyz="-0.000300415078157884" izz="0.0066373785606837"/>
    </inertial>
    <visual>
      <origin rpy="0 0 0" xyz="0 0 0"/>
      <geometry>
        <mesh filename="$(find laika_sim)/meshes/fr_hip_link.STL"/>
      </geometry>
      <material name="hip"/>
    </visual>
    <collision>
      <origin rpy="0 0 0" xyz="0 0 0"/>
      <geometry>
        <mesh filename="$(find laika_sim)/meshes/fr_hip_link.STL"/>
      </geometry>
    </collision>
  </link>
  <link name="fr_upper_link">
    <inertial>
      <origin rpy="0 0 0" xyz="0.13279490605807 0 0.018"/>
      <mass value="0.978822517757407"/>
      <inertia ixx="0.000632067195788266" ixy="-1.90203589551556E-19" ixz="1.78966921687452E-20" iyy="0.0103666862101367" iyz="8.40130980121276E-21" izz="0.0107770527681284"/>
    </inertial>
    <visual>
      <origin rpy="0 0 0" xyz="0 0 0"/>
      <geometry>
        <mesh filename="$(find laika_sim)/meshes/fl_upper_link.STL"/>
      </geometry>
      <material name="upper"/>
    </visual>
    <collision>
      <origin rpy="0 0 0" xyz="0 0 0"/>
      <geometry>
        <mesh filename="$(find laika_sim)/meshes/fl_upper_link.STL"/>
      </geometry>
    </collision>
  </link>
  <link name="fr_lower_link">
    <inertial>
      <origin rpy="0 0 0" xyz="-0.156194569361723 -0.0439524151267173 0.0125"/>
      <mass value="0.262408631372316"/>
      <inertia ixx="7.87592224730253E-05" ixy="-0.000247209665534184" ixz="3.8450329246653E-20" iyy="0.00476565441187624" iyz="-8.47751430038427E-22" izz="0.00482182622024161"/>
    </inertial>
    <visual>
      <origin rpy="0 0 0" xyz="0 0 0"/>
      <geometry>
        <mesh filename="$(find laika_sim)/meshes/fr_lower_link.STL"/>
      </geometry>
      <material name="lower"/>
    </visual>
    <collision>
      <origin rpy="0 0 0" xyz="0 0 0"/>
      <geometry>
        <mesh filename="$(find laika_sim)/meshes/fr_lower_link.STL"/>
      </geometry>
    </collision>
  </link>

  <!-- FR JOINTS -->
  <joint name="fr_lat_joint" type="revolute">
    <origin rpy="-1.5708 0 -1.5708" xyz="-0.043 -0.3075 0.116"/>
    <parent link="body_link"/>
    <child link="fr_hip_link"/>
    <axis xyz="1 0 0"/>
    <limit effort="100" lower="-0.5" upper="0.3" velocity="100"/>
    <dynamics damping="${damping}" friction="${friction}"/>
  </joint>
  <joint name="fr_hip_joint" type="revolute">
    <origin rpy="0 0 3.1416" xyz="0 0.046 -0.126"/>
    <parent link="fr_hip_link"/>
    <child link="fr_upper_link"/>
    <axis xyz="0 0 -1"/>
    <limit effort="100" lower="0" upper="${pi/2}" velocity="100"/>
    <dynamics damping="${damping}" friction="${friction}"/>
  </joint>
  <joint name="fr_knee_joint" type="revolute">
    <origin rpy="0 0 0.04573" xyz="0.35 0 0.0055"/>
    <parent link="fr_upper_link"/>
    <child link="fr_lower_link"/>
    <axis xyz="0 0 1"/>
    <limit effort="100" lower="0" upper="${pi}" velocity="100"/>
    <dynamics damping="${damping}" friction="${friction}"/>
  </joint>

  <!-- BR LINKS -->
  <link name="br_hip_link">
    <inertial>
      <origin rpy="0 0 0" xyz="-1.93920089430755E-08 0.00319763205128837 -0.0477002276240959"/>
      <mass value="1.69584433341635"/>
      <inertia ixx="0.00584981474763868" ixy="-2.11198615753673E-10" ixz="4.00957614557564E-11" iyy="0.00304591016123343" iyz="-0.000300415078157884" izz="0.00663737856068369"/>
    </inertial>
    <visual>
      <origin rpy="0 0 0" xyz="0 0 0"/>
      <geometry>
        <mesh filename="$(find laika_sim)/meshes/br_hip_link.STL"/>
      </geometry>
      <material name="hip"/>
    </visual>
    <collision>
      <origin rpy="0 0 0" xyz="0 0 0"/>
      <geometry>
        <mesh filename="$(find laika_sim)/meshes/br_hip_link.STL"/>
      </geometry>
    </collision>
  </link>
  <link name="br_upper_link">
    <inertial>
      <origin rpy="0 0 0" xyz="0.13279490605807 0 0.018"/>
      <mass value="0.978822517757407"/>
      <inertia ixx="0.000632067195788267" ixy="3.37896395172026E-19" ixz="7.84748085233969E-20" iyy="0.0103666862101367" iyz="-1.53616731582422E-20" izz="0.0107770527681284"/>
    </inertial>
    <visual>
      <origin rpy="0 0 0" xyz="0 0 0"/>
      <geometry>
        <mesh filename="$(find laika_sim)/meshes/br_upper_link.STL"/>
      </geometry>
      <material name="upper"/>
    </visual>
    <collision>
      <origin rpy="0 0 0" xyz="0 0 0"/>
      <geometry>
        <mesh filename="$(find laika_sim)/meshes/br_upper_link.STL"/>
      </geometry>
    </collision>
  </link>
  <link name="br_lower_link">
    <inertial>
      <origin rpy="0 0 0" xyz="-0.156194569361722 -0.0439524151267176 0.0125"/>
      <mass value="0.262408631372316"/>
      <inertia ixx="7.87592224730265E-05" ixy="-0.000247209665534194" ixz="8.30734337313417E-20" iyy="0.00476565441187624" iyz="1.22460571194453E-21" izz="0.00482182622024161"/>
    </inertial>
    <visual>
      <origin rpy="0 0 0" xyz="0 0 0"/>
      <geometry>
        <mesh filename="$(find laika_sim)/meshes/br_lower_link.STL"/>
      </geometry>
      <material name="lower"/>
    </visual>
    <collision>
      <origin rpy="0 0 0" xyz="0 0 0"/>
      <geometry>
        <mesh filename="$(find laika_sim)/meshes/br_lower_link.STL"/>
      </geometry>
    </collision>
  </link>

  <!-- BR JOINTS -->
  <joint name="br_lat_joint" type="revolute">
    <origin rpy="-1.5708 0 -1.5708" xyz="-0.043 0.3075 0.116"/>
    <parent link="body_link"/>
    <child link="br_hip_link"/>
    <axis xyz="1 0 0"/>
    <limit effort="100" lower="-0.5" upper="0.3" velocity="100"/>
    <dynamics damping="${damping}" friction="${friction}"/>
  </joint>
  <joint name="br_hip_joint" type="revolute">
    <origin rpy="0 0 3.1416" xyz="0 0.046 -0.126"/>
    <parent link="br_hip_link"/>
    <child link="br_upper_link"/>
    <axis xyz="0 0 -1"/>
    <limit effort="100" lower="0" upper="${pi/2}" velocity="100"/>
    <dynamics damping="${damping}" friction="${friction}"/>
  </joint>
  <joint name="br_knee_joint" type="revolute">
    <origin rpy="0 0 0.04573" xyz="0.35 0 0.0055"/>
    <parent link="br_upper_link"/>
    <child link="br_lower_link"/>
    <axis xyz="0 0 1"/>
    <limit effort="100" lower="0" upper="${pi}" velocity="100"/>
    <dynamics damping="${damping}" friction="${friction}"/>
  </joint>

  <!-- BL LINKS -->
  <link name="bl_hip_link">
    <inertial>
      <origin rpy="0 0 0" xyz="-1.93920089430755E-08 0.00319763205128837 -0.0477002276240959"/>
      <mass value="1.69584433341635"/>
      <inertia ixx="0.00584981474763868" ixy="-2.11198615753673E-10" ixz="4.00957614557564E-11" iyy="0.00304591016123343" iyz="-0.000300415078157884" izz="0.00663737856068369"/>
    </inertial>
    <visual>
      <origin rpy="0 0 0" xyz="0 0 0"/>
      <geometry>
        <mesh filename="$(find laika_sim)/meshes/bl_hip_link.STL"/>
      </geometry>
      <material name="hip"/>
    </visual>
    <collision>
      <origin rpy="0 0 0" xyz="0 0 0"/>
      <geometry>
        <mesh filename="$(find laika_sim)/meshes/bl_hip_link.STL"/>
      </geometry>
    </collision>
  </link>
  <link name="bl_upper_link">
    <inertial>
      <origin rpy="0 0 0" xyz="0.132794906058073 -0.000455732183043289 0.0179942298578352"/>
      <mass value="0.978822517757406"/>
      <inertia ixx="0.000632067195788268" ixy="-1.45050936920554E-10" ixz="-3.67210072791955E-12" iyy="0.0103669492672926" iyz="-1.03865615357797E-05" izz="0.0107767897109725"/>
    </inertial>
    <visual>
      <origin rpy="0 0 0" xyz="0 0 0"/>
      <geometry>
        <mesh filename="$(find laika_sim)/meshes/bl_upper_link.STL"/>
      </geometry>
      <material name="upper"/>
    </visual>
    <collision>
      <origin rpy="0 0 0" xyz="0 0 0"/>
      <geometry>
        <mesh filename="$(find laika_sim)/meshes/bl_upper_link.STL"/>
      </geometry>
    </collision>
  </link>
  <link name="bl_lower_link">
    <inertial>
      <origin rpy="0 0 0" xyz="-0.156194569361722 -0.0439524151267176 0.0125"/>
      <mass value="0.262408631372316"/>
      <inertia ixx="7.87592224730264E-05" ixy="-0.000247209665534194" ixz="1.44854658856677E-19" iyy="0.00476565441187624" iyz="2.01981457640735E-20" izz="0.00482182622024161"/>
    </inertial>
    <visual>
      <origin rpy="0 0 0" xyz="0 0 0"/>
      <geometry>
        <mesh filename="$(find laika_sim)/meshes/bl_lower_link.STL"/>
      </geometry>
      <material name="lower"/>
    </visual>
    <collision>
      <origin rpy="0 0 0" xyz="0 0 0"/>
      <geometry>
        <mesh filename="$(find laika_sim)/meshes/bl_lower_link.STL"/>
      </geometry>
    </collision>
  </link>

  <!-- BL JOINTS -->
  <joint name="bl_lat_joint" type="revolute">
    <origin rpy="1.5708 0 1.5708" xyz="0.043 0.3075 0.116"/>
    <parent link="body_link"/>
    <child link="bl_hip_link"/>
    <axis xyz="1 0 0"/>
    <limit effort="100" lower="-0.5" upper="0.3" velocity="100"/>
    <dynamics damping="${damping}" friction="${friction}"/>
  </joint>
  <joint name="bl_hip_joint" type="revolute">
    <origin rpy="-0.025321 0 0" xyz="0 -0.046 0.09"/>
    <parent link="bl_hip_link"/>
    <child link="bl_upper_link"/>
    <axis xyz="0 0 -1"/>
    <limit effort="100" lower="0" upper="${pi/2}" velocity="100"/>
    <dynamics damping="${damping}" friction="${friction}"/>
  </joint>
  <joint name="bl_knee_joint" type="revolute">
    <origin rpy="0.025295 -0.0011574 0.045716" xyz="0.35 -0.00013925 0.0054982"/>
    <parent link="bl_upper_link"/>
    <child link="bl_lower_link"/>
    <axis xyz="0 0 1"/>
    <limit effort="100" lower="0" upper="${pi}" velocity="100"/>
    <dynamics damping="${damping}" friction="${friction}"/>
  </joint>

  <ros2_control name="GazeboSystem" type="system">
    <hardware>
      <plugin>gz_ros2_control/GazeboSimSystem</plugin>
    </hardware>
    <joint name="fl_lat_joint">
      <command_interface name="effort" />
      <state_interface name="position" />
      <state_interface name="velocity" />
    </joint>
    <joint name="fl_hip_joint">
      <command_interface name="effort" />
      <state_interface name="position" />
      <state_interface name="velocity" />
    </joint>
    <joint name="fl_knee_joint">
      <command_interface name="effort" />
      <state_interface name="position" />
      <state_interface name="velocity" />
    </joint>
    <joint name="fr_lat_joint">
      <command_interface name="effort" />
      <state_interface name="position" />
      <state_interface name="velocity" />
    </joint>
    <joint name="fr_hip_joint">
      <command_interface name="effort" />
      <state_interface name="position" />
      <state_interface name="velocity" />
    </joint>
    <joint name="fr_knee_joint">
      <command_interface name="effort" />
      <state_interface name="position" />
      <state_interface name="velocity" />
    </joint>
    <joint name="bl_lat_joint">
      <command_interface name="effort" />
      <state_interface name="position" />
      <state_interface name="velocity" />
    </joint>
    <joint name="bl_hip_joint">
      <command_interface name="effort" />
      <state_interface name="position" />
      <state_interface name="velocity" />
    </joint>
    <joint name="bl_knee_joint">
      <command_interface name="effort" />
      <state_interface name="position" />
      <state_interface name="velocity" />
    </joint>
    <joint name="br_lat_joint">
      <command_interface name="effort" />
      <state_interface name="position" />
      <state_interface name="velocity" />
    </joint>
    <joint name="br_hip_joint">
      <command_interface name="effort" />
      <state_interface name="position" />
      <state_interface name="velocity" />
    </joint>
    <joint name="br_knee_joint">
      <command_interface name="effort" />
      <state_interface name="position" />
      <state_interface name="velocity" />
    </joint>
  </ros2_control>

  <gazebo>
    <plugin filename="libgz_ros2_control-system.so" name="gz_ros2_control::GazeboSimROS2ControlPlugin">
      <parameters>$(find laika_sim)/config/laika_controller.yaml</parameters>
    </plugin>
  </gazebo>
</robot>
